Workbook

Sheet README
A1: Harry Shenk — manual mentor-payout calculation
A2: Built 2026-07-25 from the Notion Mentees Database (roster), the HJG raw-data export (invoice dates + amounts), and reconciled against the dashboard's June-2026 payout build.
A4: Headline
A5: Manual method, June 2026 | B5: ='June Reconciliation'!B6 -> 2983.5935
A6: Dashboard paystub, June 2026 (reviewed) | B6: ='June Reconciliation'!B10 -> 3273.5
A7: Variance | B7: =('June Reconciliation'!B6-'June Reconciliation'!B10) -> -289.90645
A9: The method (your formulas, unchanged)
A10: Amount = tier price billed on the invoice's mentoring line, plus any adjustment you switch ON
A11: Month Start = the invoice date (CoachAccountable date_of)
A12: Harry's Percentage = the mentor revenue share for that calendar month
A13: % of mo to be paid = 1 - DAY(Month Start) / DAY(EOMONTH(Month Start, 0))
A14: Harry's Pay = Amount x Pct x %ofMo + (1 - %ofMo prior) x Amount prior x Pct prior
A15: Assured Take-Home = Amount x Pct
A17: Decisions you made 2026-07-25
A18: 1. Proration uses REAL days in the month (May = 31, June = 30), per your =1-DAY()/DAY(EOMONTH()) formula.
A19: 2. Amount = tier price. Credits and discounts are listed on the Adjustments tab, defaulted OFF, and you
A20: can switch any of them ON with a Y/N toggle — the whole workbook recalculates.
A21: 3. David Weaver's two separate May invoices get two columns; Josh Lehman's duplicated 4x line on one
... A49: Yellow fill = a cell you are meant to edit. Red fill = a variance or conflict to look at.

Sheet Mentee Blocks
A1: Harry Shenk — mentee-by-mentee payout calculation
A2: One block per mentee, oldest mentoring invoice first. Column widths hold up to 13 months; the Total column is at the far right.
A4: Alex Reiff | B4: client 277779 · Notion: 2x Mentoring · 2x current · 8 month column(s)
A5: Month | B5: December 2025 | C5: January 2026 | D5: February 2026 | E5: March 2026 | F5: April 2026 | G5: May 2026 | H5: June 2026 | I5: July 2026 | O5: TOTAL | P5: Residual
A6: Invoice # | B6: 3803 | C6: 3857 | D6: 3910 | E6: 3958 | F6: 4015 | G6: 4071 | H6: 4170 | I6: — no invoice —
A7: Tier price billed | B7: 425 | C7: 425 | D7: 425 | E7: 425 | F7: 425 | G7: 425 | H7: 265 | I7: 0
A8: Adjustments applied | B8: 0 | C8: 0 | D8: 0 | E8: 0 | F8: 0 | G8: 0 | H8: 0 | I8: 0
A9: Amount | B9: =B7+B8 -> 425 | C9: =C7+C8 -> 425 | D9: =D7+D8 -> 425 | E9: =E7+E8 -> 425 | F9: =F7+F8 -> 425 | G9: =G7+G8 -> 425 | H9: =H7+H8 -> 265 | I9: =I7+I8 -> 0
A10: Month Start | B10: 45999 | C10: 46030 | D10: 46061 | E10: 46089 | F10: 46120 | G10: 46150 | H10: 46194 | I10: —
A11: Harry's Percentage | B11: 0.6 | C11: 0.6 | D11: 0.6 | E11: 0.6 | F11: 0.6 | G11: 0.6 | H11: 0.6 | I11: 0.6
A12: % of mo to be paid | B12: =1-DAY(B10)/DAY(EOMONTH(B10,0)) -> 0.74193548 | C12: =1-DAY(C10)/DAY(EOMONTH(C10,0)) -> 0.74193548 | D12: =1-DAY(D10)/DAY(EOMONTH(D10,0)) -> 0.71428571 | E12: =1-DAY(E10)/DAY(EOMONTH(E10,0)) -> 0.74193548 | F12: =1-DAY(F10)/DAY(EOMONTH(F10,0)) -> 0.73333333 | G12: =1-DAY(G10)/DAY(EOMONTH(G10,0)) -> 0.74193548 | H12: =1-DAY(H10)/DAY(EOMONTH(H10,0)) -> 0.3 | I12: 0
A13: Harry's Pay | B13: =B9*B11*B12 -> 189.19355 | C13: =C9*C11*C12+(1-B12)*B9*B11 -> 255 | D13: =D9*D11*D12+(1-C12)*C9*C11 -> 247.94931 | E13: =E9*E11*E12+(1-D12)*D9*D11 -> 262.05069 | F13: =F9*F11*F12+(1-E12)*E9*E11 -> 252.80645 | G13: =G9*G11*G12+(1-F12)*F9*F11 -> 257.19355 | H13: =H9*H11*H12+(1-G12)*G9*G11 -> 113.50645 | I13: =I9*I11*I12+(1-H12)*H9*H11 -> 111.3 | O13: =SUM(B13:I13) -> 1689
A14: Assured Take-Home | B14: =B9*B11 -> 255 | C14: =C9*C11 -> 255 | D14: =D9*D11 -> 255 | E14: =E9*E11 -> 255 | F14: =F9*F11 -> 255 | G14: =G9*G11 -> 255 | H14: =H9*H11 -> 159 | I14: =I9*I11 -> 0 | O14: =SUM(B14:I14) -> 1689 | P14: =O14-O13 -> 0
A17: Allen Miller | B17: client 233476 · Notion: Done (Quit OR No Mentoring) · 4x current · 8 month column(s)
A18: Month | B18: June 2024 | C18: July 2024 | D18: August 2024 | E18: September 2024 | F18: September 2024 | G18: October 2024 | H18: November 2024 | I18: December 2024 | O18: TOTAL | P18: Residual
A19: Invoice # | B19: 3065 | C19: 3117 | D19: — no invoice — | E19: 3164 | F19: 3198 | G19: 3239 | H19: 3269 | I19: — no invoice —
A20: Tier price billed | B20: 425 | C20: 425 | D20: 0 | E20: 425 | F20: 425 | G20: 425 | H20: 425 | I20: 0
A21: Adjustments applied | B21: 0 | C21: 0 | D21: 0 | E21: 0 | F21: 0 | G21: 0 | H21: 0 | I21: 0
A22: Amount | B22: =B20+B21 -> 425 | C22: =C20+C21 -> 425 | D22: =D20+D21 -> 0 | E22: =E20+E21 -> 425 | F22: =F20+F21 -> 425 | G22: =G20+G21 -> 425 | H22: =H20+H21 -> 425 | I22: =I20+I21 -> 0
A23: Month Start | B23: 45463 | C23: 45504 | D23: — | E23: 45536 | F23: 45559 | G23: 45590 | H23: 45621 | I23: —
A24: Harry's Percentage | B24: 0.5 | C24: 0.6 | D24: 0.6 | E24: 0.6 | F24: 0.6 | G24: 0.6 | H24: 0.6 | I24: 0.6
A25: % of mo to be paid | B25: =1-DAY(B23)/DAY(EOMONTH(B23,0)) -> 0.33333333 | C25: =1-DAY(C23)/DAY(EOMONTH(C23,0)) -> 0 | D25: 0 | E25: =1-DAY(E23)/DAY(EOMONTH(E23,0)) -> 0.96666667 | F25: =1-DAY(F23)/DAY(EOMONTH(F23,0)) -> 0.2 | G25: =1-DAY(G23)/DAY(EOMONTH(G23,0)) -> 0.19354839 | H25: =1-DAY(H23)/DAY(EOMONTH(H23,0)) -> 0.16666667 | I25: 0
A26: Harry's Pay | B26: =B22*B24*B25 -> 70.833333 | C26: =C22*C24*C25+(1-B25)*B22*B24 -> 141.66667 | D26: =D22*D24*D25+(1-C25)*C22*C24 -> 255 | E26: =E22*E24*E25+(1-D25)*D22*D24 -> 246.5 | F26: =F22*F24*F25+(1-E25)*E22*E24 -> 59.5 | G26: =G22*G24*G25+(1-F25)*F22*F24 -> 253.35484 | H26: =H22*H24*H25+(1-G25)*G22*G24 -> 248.14516 | I26: =I22*I24*I25+(1-H25)*H22*H24 -> 212.5 | O26: =SUM(B26:I26) -> 1487.5
A27: Assured Take-Home | B27: =B22*B24 -> 212.5 | C27: =C22*C24 -> 255 | D27: =D22*D24 -> 0 | E27: =E22*E24 -> 255 | F27: =F22*F24 -> 255 | G27: =G22*G24 -> 255 | H27: =H22*H24 -> 255 | I27: =I22*I24 -> 0 | O27: =SUM(B27:I27) -> 1487.5 | P27: =O27-O26 -> 0
A30: Brandon Burkholder | B30: client 268818 · Notion: 4x Mentoring · 4x current · 11 month column(s)
A31: Month | B31: October 2025 | C31: November 2025 | D31: December 2025 | E31: January 2026 | F31: February 2026 | G31: March 2026 | H31: April 2026 | I31: May 2026 | J31: June 2026 | K31: July 2026 | L31: August 2026 | O31: TOTAL | P31: Residual
A32: Invoice # | B32: 3724 | C32: 3779 | D32: 3833 | E32: — no invoice — | F32: 3902 | G32: — no invoice — | H32: — no invoice — | I32: 4100 | J32: 4167 | K32: 4230 | L32: — no invoice —
A33: Tier price billed | B33: 425 | C33: 425 | D33: 425 | E33: 0 | F33: 425 | G33: 0 | H33: 0 | I33: 425 | J33: 425 | K33: 425 | L33: 0
A34: Adjustments applied | B34: 0 | C34: 0 | D34: 0 | E34: 0 | F34: =SUMIF(Adjustments!$C$5:$C$14,F32,Adjustments!$H$5:$H$14) -> 0 | G34: 0 | H34: 0 | I34: 0 | J34: 0 | K34: 0 | L34: 0
A35: Amount | B35: =B33+B34 -> 425 | C35: =C33+C34 -> 425 | D35: =D33+D34 -> 425 | E35: =E33+E34 -> 0 | F35: =F33+F34 -> 425 | G35: =G33+G34 -> 0 | H35: =H33+H34 -> 0 | I35: =I33+I34 -> 425 | ... L35: =L33+L34 -> 0
A36: Month Start | B36: 45956 | C36: 45987 | D36: 46017 | E36: — | F36: 46055 | G36: — | H36: — | I36: 46161 | J36: 46192 | K36: 46222 | L36: —
A37: Harry's Percentage | B37: 0.6 | C37: 0.6 | D37: 0.6 | E37: 0.6 | F37: 0.6 | G37: 0.6 | H37: 0.6 | I37: 0.6 | J37: 0.6 | K37: 0.6 | L37: 0.6
A38: % of mo to be paid | B38: =1-DAY(B36)/DAY(EOMONTH(B36,0)) -> 0.16129032 | C38: =1-DAY(C36)/DAY(EOMONTH(C36,0)) -> 0.13333333 | D38: =1-DAY(D36)/DAY(EOMONTH(D36,0)) -> 0.16129032 | E38: 0 | F38: =1-DAY(F36)/DAY(EOMONTH(F36,0)) -> 0.92857143 | G38: 0 | H38: 0 | I38: =1-DAY(I36)/DAY(EOMONTH(I36,0)) -> 0.38709677 | J38: =1-DAY(J36)/DAY(EOMONTH(J36,0)) -> 0.36666667 | K38: =1-DAY(K36)/DAY(EOMONTH(K36,0)) -> 0.38709677 | L38: 0
A39: Harry's Pay | B39: =B35*B37*B38 -> 41.129032 | C39: =C35*C37*C38+(1-B38)*B35*B37 -> 247.87097 | D39: =D35*D37*D38+(1-C38)*C35*C37 -> 262.12903 | E39: =E35*E37*E38+(1-D38)*D35*D37 -> 213.87097 | F39: =F35*F37*F38+(1-E38)*E35*E37 -> 236.78571 | G39: =G35*G37*G38+(1-F38)*F35*F37 -> 18.214286 | H39: =H35*H37*H38+(1-G38)*G35*G37 -> 0 | I39: =I35*I37*I38+(1-H38)*H35*H37 -> 98.709677 | J39: =J35*J37*J38+(1-I38)*I35*I37 -> 249.79032 | ... L39: =L35*L37*L38+(1-K38)*K35*K37 -> 156.29032 | O39: =SUM(B39:L39) -> 1785
A40: Assured Take-Home | B40: =B35*B37 -> 255 | C40: =C35*C37 -> 255 | D40: =D35*D37 -> 255 | E40: =E35*E37 -> 0 | F40: =F35*F37 -> 255 | G40: =G35*G37 -> 0 | H40: =H35*H37 -> 0 | I40: =I35*I37 -> 255 | ... L40: =L35*L37 -> 0 | O40: =SUM(B40:L40) -> 1785 | P40: =O40-O39 -> 0
A43: Brennan Petersheim | B43: client 294186 · Notion: 4x Mentoring · 4x current · 2 month column(s)
A44: Month | B44: July 2026 | C44: August 2026 | O44: TOTAL | P44: Residual
A45: Invoice # | B45: 4193 | C45: — no invoice —
A46: Tier price billed | B46: 425 | C46: 0
A47: Adjustments applied | B47: 0 | C47: 0
...

Sheet Adjustments
A1: Adjustments — credits, discounts and duplicate lines
A2: Switch Include? to Y to let a line reduce (or raise) the pay basis. Everything defaults to N, which is 'pay Harry on the tier price'. The Mentee Blocks tab recalculates automatically.
A4: Key | B4: Mentee | C4: Invoice # | D4: Invoice date | E4: Line item | F4: Amount | G4: Include? | H4: Effective
A5: 3902#cr1 | B5: Brandon Burkholder | C5: 3902 | D5: 46055 | E5: Credit for unused appointments [credit / discount] | F5: -212.5 | G5: N | H5: =IF(G5="Y",F5,0) -> 0
A6: 4085#cr1 | B6: Daryl Bowman | C6: 4085 | D6: 46155 | E6: Credit for accidental 4x invoice [credit / discount] | F6: -160 | G6: N | H6: =IF(G6="Y",F6,0) -> 0
A7: 4109#dup1 | B7: Josh Lehman | C7: 4109 | D7: 46153 | E7: MN Subscription | (4x Month) Zoom Meetings (Harry Shenk) [duplicate mentoring line] | F7: 425 | G7: N | H7: =IF(G7="Y",F7,0) -> 0
A8: 4109#cr2 | B8: Josh Lehman | C8: 4109 | D8: 46153 | E8: Credit for previous payment [credit / discount] | F8: -175 | G8: N | H8: =IF(G8="Y",F8,0) -> 0
A9: 4109#cr3 | B9: Josh Lehman | C9: 4109 | D9: 46153 | E9: "Apology" Credit [credit / discount] | F9: -50 | G9: N | H9: =IF(G9="Y",F9,0) -> 0
A10: 4083#cr1 | B10: Kendrick Sensenig | C10: 4083 | D10: 46155 | E10: First-Month Discount Credit [credit / discount] | F10: -70 | G10: N | H10: =IF(G10="Y",F10,0) -> 0
A11: 4157#cr1 | B11: Luke Smucker | C11: 4157 | D11: 46188 | E11: Credit from overpayment last month (Harry Shenk) [credit / discount] | F11: -160 | G11: N | H11: =IF(G11="Y",F11,0) -> 0
A12: 4149#cr1 | B12: Nelson Miller | C12: 4149 | D12: 46184 | E12: Credit from payments [credit / discount] | F12: -250 | G12: N | H12: =IF(G12="Y",F12,0) -> 0
A13: 4185#cr1 | B13: Russ Zehr | C13: 4185 | D13: 46202 | E13: Credit for the JYF Fee [credit / discount] | F13: -175 | G13: N | H13: =IF(G13="Y",F13,0) -> 0
A14: 3643#cr1 | B14: Wynn Miller | C14: 3643 | D14: 45908 | E14: Subscription Credit from Overpayment in August [credit / discount] | F14: -250 | G14: N | H14: =IF(G14="Y",F14,0) -> 0
E16: Total adjustment currently applied | H16: =SUM(H5:H14) -> 0
A18: Note: the dashboard's June build had a reviewer remove exactly these credits, which is why its 'Engine payout' ($3,017.70) and 'Effective payout' ($3,273.50) differ.

Sheet Monthly Roll-up
A1: Harry Shenk — total pay by calendar month (manual method)
A2: Each cell links straight to that mentee's Harry's Pay cell on the Mentee Blocks tab.
A4: Mentee | B4: 2024-06 | C4: 2024-07 | D4: 2024-08 | E4: 2024-09 | F4: 2024-10 | G4: 2024-11 | H4: 2024-12 | I4: 2025-01 | J4: 2025-02 | K4: 2025-03 | L4: 2025-04 | M4: 2025-05 | N4: 2025-06 | O4: 2025-07 | P4: 2025-08 | Q4: 2025-09 | R4: 2025-10 | S4: 2025-11 | T4: 2025-12 | U4: 2026-01 | V4: 2026-02 | W4: 2026-03 | X4: 2026-04 | Y4: 2026-05 | Z4: 2026-06 | AA4: 2026-07 | AB4: 2026-08 | AC4: TOTAL
A5: Alex Reiff | B5: 0 | C5: 0 | D5: 0 | E5: 0 | F5: 0 | G5: 0 | H5: 0 | I5: 0 | J5: 0 | K5: 0 | L5: 0 | M5: 0 | N5: 0 | O5: 0 | P5: 0 | Q5: 0 | R5: 0 | S5: 0 | T5: ='Mentee Blocks'!B13 -> 189.19355 | U5: ='Mentee Blocks'!C13 -> 255 | V5: ='Mentee Blocks'!D13 -> 247.94931 | W5: ='Mentee Blocks'!E13 -> 262.05069 | X5: ='Mentee Blocks'!F13 -> 252.80645 | Y5: ='Mentee Blocks'!G13 -> 257.19355 | Z5: ='Mentee Blocks'!H13 -> 113.50645 | AA5: ='Mentee Blocks'!I13 -> 111.3 | AB5: 0 | AC5: =SUM(B5:AB5) -> 1689
A6: Allen Miller | B6: ='Mentee Blocks'!B26 -> 70.833333 | C6: ='Mentee Blocks'!C26 -> 141.66667 | D6: ='Mentee Blocks'!D26 -> 255 | E6: ='Mentee Blocks'!E26+'Mentee Blocks'!F26 -> 306 | F6: ='Mentee Blocks'!G26 -> 253.35484 | G6: ='Mentee Blocks'!H26 -> 248.14516 | H6: ='Mentee Blocks'!I26 -> 212.5 | I6: 0 | J6: 0 | K6: 0 | L6: 0 | M6: 0 | N6: 0 | O6: 0 | P6: 0 | Q6: 0 | R6: 0 | S6: 0 | T6: 0 | U6: 0 | V6: 0 | W6: 0 | X6: 0 | Y6: 0 | Z6: 0 | AA6: 0 | AB6: 0 | AC6: =SUM(B6:AB6) -> 1487.5
A7: Brandon Burkholder | B7: 0 | C7: 0 | D7: 0 | E7: 0 | F7: 0 | G7: 0 | H7: 0 | I7: 0 | J7: 0 | K7: 0 | L7: 0 | M7: 0 | N7: 0 | O7: 0 | P7: 0 | Q7: 0 | R7: ='Mentee Blocks'!B39 -> 41.129032 | S7: ='Mentee Blocks'!C39 -> 247.87097 | T7: ='Mentee Blocks'!D39 -> 262.12903 | U7: ='Mentee Blocks'!E39 -> 213.87097 | V7: ='Mentee Blocks'!F39 -> 236.78571 | W7: ='Mentee Blocks'!G39 -> 18.214286 | X7: ='Mentee Blocks'!H39 -> 0 | Y7: ='Mentee Blocks'!I39 -> 98.709677 | ... AB7: ='Mentee Blocks'!L39 -> 156.29032 | AC7: =SUM(B7:AB7) -> 1785
A8: Brennan Petersheim | B8: 0 | C8: 0 | D8: 0 | E8: 0 | F8: 0 | G8: 0 | H8: 0 | I8: 0 | J8: 0 | K8: 0 | L8: 0 | M8: 0 | N8: 0 | O8: 0 | P8: 0 | Q8: 0 | R8: 0 | S8: 0 | T8: 0 | U8: 0 | V8: 0 | W8: 0 | X8: 0 | Y8: 0 | Z8: 0 | AA8: ='Mentee Blocks'!B52 -> 238.54839 | AB8: ='Mentee Blocks'!C52 -> 16.451613 | AC8: =SUM(B8:AB8) -> 255
A9: Brett Wengerd | B9: 0 | C9: 0 | D9: 0 | E9: 0 | F9: 0 | G9: 0 | H9: 0 | I9: 0 | J9: 0 | K9: 0 | L9: 0 | M9: 0 | N9: 0 | O9: 0 | P9: 0 | Q9: ='Mentee Blocks'!B65 -> 93.5 | R9: ='Mentee Blocks'!C65 -> 260.20968 | S9: ='Mentee Blocks'!D65 -> 249.79032 | T9: ='Mentee Blocks'!E65 -> 260.20968 | U9: ='Mentee Blocks'!F65 -> 255 | V9: ='Mentee Blocks'!G65 -> 238.25461 | W9: ='Mentee Blocks'!H65 -> 271.74539 | X9: ='Mentee Blocks'!I65 -> 249.79032 | ... AA9: ='Mentee Blocks'!L65 -> 161.5 | AB9: 0 | AC9: =SUM(B9:AB9) -> 2550
A10: Cade Byers | B10: 0 | C10: 0 | D10: 0 | E10: 0 | F10: 0 | G10: 0 | H10: 0 | I10: 0 | J10: 0 | K10: 0 | L10: 0 | M10: 0 | N10: 0 | O10: 0 | P10: 0 | Q10: 0 | R10: 0 | S10: 0 | T10: 0 | U10: 0 | V10: 0 | W10: 0 | X10: 0 | Y10: ='Mentee Blocks'!B78 -> 148.06452 | Z10: ='Mentee Blocks'!C78 -> 251.43548 | AA10: ='Mentee Blocks'!D78 -> 258.56452 | AB10: ='Mentee Blocks'!E78 -> 106.93548 | AC10: =SUM(B10:AB10) -> 765
A11: Darin Riehl | B11: 0 | C11: 0 | D11: 0 | E11: 0 | F11: 0 | G11: 0 | H11: 0 | I11: 0 | J11: 0 | K11: 0 | L11: 0 | M11: 0 | N11: 0 | O11: 0 | P11: 0 | Q11: 0 | R11: ='Mentee Blocks'!B91 -> 106.93548 | S11: ='Mentee Blocks'!C91 -> 250.06452 | T11: ='Mentee Blocks'!D91 -> 259.93548 | U11: ='Mentee Blocks'!E91 -> 255 | V11: ='Mentee Blocks'!F91 -> 148.06452 | W11: 0 | X11: 0 | Y11: 0 | Z11: 0 | AA11: 0 | AB11: 0 | AC11: =SUM(B11:AB11) -> 1020
A12: Daryl Bowman | B12: 0 | C12: 0 | D12: 0 | E12: 0 | F12: 0 | G12: 0 | H12: 0 | I12: 0 | J12: 0 | K12: 0 | L12: 0 | M12: 0 | N12: 0 | O12: 0 | P12: 0 | Q12: 0 | R12: ='Mentee Blocks'!B104 -> 139.83871 | S12: ='Mentee Blocks'!C104 -> 251.16129 | T12: ='Mentee Blocks'!D104 -> 258.83871 | U12: ='Mentee Blocks'!E104 -> 255 | V12: ='Mentee Blocks'!F104 -> 242.66129 | W12: ='Mentee Blocks'!G104 -> 267.33871 | X12: ='Mentee Blocks'!H104 -> 251.16129 | Y12: ='Mentee Blocks'!I104 -> 211.32258 | Z12: ='Mentee Blocks'!J104 -> 66.677419 | AA12: 0 | AB12: 0 | AC12: =SUM(B12:AB12) -> 1944
A13: David Weaver | B13: 0 | C13: 0 | D13: 0 | E13: 0 | F13: 0 | G13: 0 | H13: 0 | I13: 0 | J13: 0 | K13: 0 | L13: 0 | M13: 0 | N13: 0 | O13: 0 | P13: 0 | Q13: 0 | R13: 0 | S13: 0 | T13: 0 | U13: 0 | V13: 0 | W13: 0 | X13: 0 | Y13: ='Mentee Blocks'!B117+'Mentee Blocks'!C117 -> 337.25806 | Z13: ='Mentee Blocks'!D117 -> 249.24194 | AA13: ='Mentee Blocks'!E117 -> 260.75806 | AB13: ='Mentee Blocks'!F117 -> 172.74194 | AC13: =SUM(B13:AB13) -> 1020
A14: Gordon Boone | B14: 0 | C14: 0 | D14: 0 | E14: 0 | F14: 0 | G14: 0 | H14: 0 | I14: 0 | J14: 0 | K14: 0 | L14: 0 | M14: 0 | N14: 0 | O14: 0 | P14: 0 | Q14: 0 | R14: 0 | S14: 0 | T14: 0 | U14: 0 | V14: 0 | W14: 0 | X14: 0 | Y14: 0 | Z14: ='Mentee Blocks'!B130 -> 110.5 | AA14: ='Mentee Blocks'!C130 -> 259.66129 | AB14: ='Mentee Blocks'!D130 -> 139.83871 | AC14: =SUM(B14:AB14) -> 510
A15: Harvey Stoll | B15: 0 | C15: 0 | D15: 0 | E15: 0 | F15: 0 | G15: 0 | H15: 0 | I15: ='Mentee Blocks'!B143 -> 230.32258 | J15: ='Mentee Blocks'!C143 -> 252.35599 | K15: ='Mentee Blocks'!D143 -> 257.64401 | L15: ='Mentee Blocks'!E143 -> 254.17742 | M15: ='Mentee Blocks'!F143 -> 255.82258 | N15: ='Mentee Blocks'!G143 -> 254.17742 | O15: ='Mentee Blocks'!H143 -> 255.82258 | P15: ='Mentee Blocks'!I143 -> 255 | ... R15: ='Mentee Blocks'!K143 -> 25.5 | S15: 0 | T15: 0 | U15: 0 | V15: 0 | W15: 0 | X15: 0 | Y15: 0 | Z15: 0 | AA15: 0 | AB15: 0 | AC15: =SUM(B15:AB15) -> 2295
A16: Isaiah Hursh | B16: 0 | C16: 0 | D16: 0 | E16: 0 | F16: 0 | G16: 0 | H16: 0 | I16: 0 | J16: 0 | K16: 0 | L16: 0 | M16: 0 | N16: 0 | O16: 0 | P16: 0 | Q16: 0 | R16: 0 | S16: 0 | T16: 0 | U16: 0 | V16: 0 | W16: 0 | X16: 0 | Y16: ='Mentee Blocks'!B156 -> 139.83871 | Z16: ='Mentee Blocks'!C156 -> 251.16129 | AA16: ='Mentee Blocks'!D156 -> 258.83871 | AB16: ='Mentee Blocks'!E156 -> 115.16129 | AC16: =SUM(B16:AB16) -> 765
A17: Jared Byler | B17: 0 | C17: 0 | D17: 0 | E17: 0 | F17: 0 | G17: 0 | H17: 0 | I17: 0 | J17: 0 | K17: 0 | L17: 0 | M17: 0 | N17: 0 | O17: 0 | P17: 0 | Q17: 0 | R17: 0 | S17: 0 | T17: 0 | U17: 0 | V17: 0 | W17: 0 | X17: 0 | Y17: 0 | Z17: 0 | AA17: ='Mentee Blocks'!B169 -> 90.483871 | AB17: ='Mentee Blocks'!C169 -> 164.51613 | AC17: =SUM(B17:AB17) -> 255
A18: Joel Mast | B18: 0 | C18: 0 | D18: 0 | E18: 0 | F18: 0 | G18: 0 | H18: 0 | I18: 0 | J18: 0 | K18: 0 | L18: 0 | M18: 0 | N18: 0 | O18: 0 | P18: 0 | Q18: 0 | R18: 0 | S18: 0 | T18: 0 | U18: 0 | V18: 0 | W18: 0 | X18: 0 | Y18: ='Mentee Blocks'!B182 -> 154.83871 | Z18: ='Mentee Blocks'!C182 -> 85.16129 | AA18: 0 | AB18: 0 | AC18: =SUM(B18:AB18) -> 240
A19: John Troyer | B19: 0 | C19: 0 | D19: 0 | E19: 0 | F19: 0 | G19: 0 | H19: 0 | I19: 0 | J19: 0 | K19: 0 | L19: 0 | M19: 0 | N19: 0 | O19: 0 | P19: 0 | Q19: ='Mentee Blocks'!B195 -> 8.5 | R19: ='Mentee Blocks'!C195 -> 262.95161 | S19: ='Mentee Blocks'!D195 -> 247.04839 | T19: ='Mentee Blocks'!E195 -> 262.95161 | U19: ='Mentee Blocks'!F195 -> 255 | V19: ='Mentee Blocks'!G195 -> 238.54839 | W19: ='Mentee Blocks'!H195+'Mentee Blocks'!I195 -> 287.90323 | X19: ='Mentee Blocks'!J195 -> 247.59677 | Y19: ='Mentee Blocks'!K195 -> 262.40323 | Z19: ='Mentee Blocks'!L195 -> 222.09677 | AA19: ='Mentee Blocks'!M195 -> 92.322581 | AB19: ='Mentee Blocks'!N195 -> 66.677419 | AC19: =SUM(B19:AB19) -> 2454
A20: Josh Blank | B20: 0 | C20: 0 | D20: 0 | E20: 0 | F20: 0 | G20: 0 | H20: 0 | I20: 0 | J20: 0 | K20: 0 | L20: ='Mentee Blocks'!B208 -> 204 | M20: ='Mentee Blocks'!C208 -> 256.64516 | N20: ='Mentee Blocks'!D208 -> 253.35484 | O20: ='Mentee Blocks'!E208 -> 256.64516 | P20: ='Mentee Blocks'!F208 -> 49.354839 | Q20: 0 | R20: 0 | S20: 0 | T20: 0 | U20: 0 | V20: 0 | W20: 0 | X20: 0 | Y20: 0 | Z20: 0 | AA20: 0 | AB20: 0 | AC20: =SUM(B20:AB20) -> 1020
A21: Josh Lehman | B21: 0 | C21: 0 | D21: 0 | E21: 0 | F21: 0 | G21: 0 | H21: 0 | I21: 0 | J21: 0 | K21: 0 | L21: 0 | M21: 0 | N21: 0 | O21: 0 | P21: 0 | Q21: 0 | R21: 0 | S21: 0 | T21: 0 | U21: 0 | V21: 0 | W21: 0 | X21: 0 | Y21: ='Mentee Blocks'!B221 -> 164.51613 | Z21: ='Mentee Blocks'!C221 -> 260.48387 | AA21: ='Mentee Blocks'!D221 -> 257.74194 | AB21: ='Mentee Blocks'!E221 -> 82.258065 | AC21: =SUM(B21:AB21) -> 765
A22: Kendrick Sensenig | B22: 0 | C22: 0 | D22: 0 | E22: 0 | F22: 0 | G22: 0 | H22: 0 | I22: 0 | J22: 0 | K22: 0 | L22: 0 | M22: 0 | N22: 0 | O22: 0 | P22: 0 | Q22: 0 | R22: 0 | S22: 0 | T22: 0 | U22: 0 | V22: 0 | W22: 0 | X22: 0 | Y22: ='Mentee Blocks'!B234 -> 148.06452 | Z22: ='Mentee Blocks'!C234 -> 259.93548 | AA22: ='Mentee Blocks'!D234 -> 258.29032 | AB22: ='Mentee Blocks'!E234 -> 98.709677 | AC22: =SUM(B22:AB22) -> 765
A23: Landin Troyer | B23: 0 | C23: 0 | D23: 0 | E23: 0 | F23: 0 | G23: 0 | H23: 0 | I23: 0 | J23: 0 | K23: 0 | L23: 0 | M23: ='Mentee Blocks'!B247+'Mentee Blocks'!C247 -> 255 | N23: ='Mentee Blocks'!D247 -> 260.3 | O23: ='Mentee Blocks'!E247 -> 163.95806 | P23: ='Mentee Blocks'!F247 -> 159 | Q23: ='Mentee Blocks'!G247 -> 151.64194 | R23: ='Mentee Blocks'!H247 -> 89.712903 | S23: ='Mentee Blocks'!I247 -> 84.287097 | T23: ='Mentee Blocks'!J247 -> 84.1 | U23: 0 | V23: 0 | W23: 0 | X23: 0 | Y23: 0 | Z23: 0 | AA23: 0 | AB23: 0 | AC23: =SUM(B23:AB23) -> 1248
A24: Lavon Stoltzfus | B24: 0 | C24: 0 | D24: 0 | E24: 0 | F24: 0 | G24: 0 | H24: 0 | I24: 0 | J24: 0 | K24: 0 | L24: 0 | M24: 0 | N24: 0 | O24: 0 | P24: ='Mentee Blocks'!B260 -> 222.09677 | Q24: ='Mentee Blocks'!C260 -> 253.90323 | R24: ='Mentee Blocks'!D260 -> 256.09677 | S24: ='Mentee Blocks'!E260 -> 253.90323 | T24: ='Mentee Blocks'!F260 -> 256.09677 | U24: ='Mentee Blocks'!G260 -> 255 | V24: ='Mentee Blocks'!H260+'Mentee Blocks'!I260 -> 339.01037 | W24: ='Mentee Blocks'!J260 -> 169.44124 | X24: ='Mentee Blocks'!K260 -> 155.75161 | Y24: ='Mentee Blocks'!L260 -> 162.24839 | Z24: ='Mentee Blocks'!M260 -> 97.451613 | AA24: 0 | AB24: 0 | AC24: =SUM(B24:AB24) -> 2421
A25: Luke Smucker | B25: 0 | C25: 0 | D25: 0 | E25: 0 | F25: 0 | G25: 0 | H25: 0 | I25: 0 | J25: 0 | K25: 0 | L25: 0 | M25: 0 | N25: 0 | O25: 0 | P25: 0 | Q25: 0 | R25: ='Mentee Blocks'!B273 -> 180.96774 | S25: ='Mentee Blocks'!C273 -> 252.53226 | T25: ='Mentee Blocks'!D273 -> 257.46774 | U25: ='Mentee Blocks'!E273 -> 255 | V25: ='Mentee Blocks'!F273 -> 247.06797 | W25: ='Mentee Blocks'!G273 -> 262.93203 | X25: ='Mentee Blocks'!H273 -> 252.53226 | Y25: ='Mentee Blocks'!I273 -> 257.46774 | ... AB25: ='Mentee Blocks'!L273 -> 76.935484 | AC25: =SUM(B25:AB25) -> 2358
A26: Myles Miller | B26: 0 | C26: 0 | D26: 0 | E26: 0 | F26: 0 | G26: 0 | H26: 0 | I26: 0 | J26: 0 | K26: 0 | L26: 0 | M26: 0 | N26: 0 | O26: 0 | P26: ='Mentee Blocks'!B286 -> 213.87097 | Q26: ='Mentee Blocks'!C286 -> 253.62903 | R26: ='Mentee Blocks'!D286 -> 256.37097 | S26: ='Mentee Blocks'!E286 -> 253.62903 | T26: ='Mentee Blocks'!F286 -> 256.37097 | U26: ='Mentee Blocks'!G286 -> 255 | V26: ='Mentee Blocks'!H286 -> 250.59332 | W26: ='Mentee Blocks'!I286 -> 259.40668 | ... AB26: ='Mentee Blocks'!N286 -> 41.129032 | AC26: =SUM(B26:AB26) -> 3060
A27: Nelson Miller | B27: 0 | C27: 0 | D27: 0 | E27: 0 | F27: 0 | G27: 0 | H27: 0 | I27: 0 | J27: 0 | K27: 0 | L27: 0 | M27: 0 | N27: 0 | O27: 0 | P27: 0 | Q27: 0 | R27: 0 | S27: 0 | T27: 0 | U27: ='Mentee Blocks'!B299 -> 180.96774 | V27: ='Mentee Blocks'!C299 -> 247.06797 | W27: ='Mentee Blocks'!D299 -> 262.93203 | X27: ='Mentee Blocks'!E299 -> 74.032258 | Y27: ='Mentee Blocks'!F299 -> 0 | Z27: ='Mentee Blocks'!G299 -> 100.7 | AA27: ='Mentee Blocks'!H299 -> 58.3 | AB27: 0 | AC27: =SUM(B27:AB27) -> 924
A28: Russ Zehr | B28: 0 | C28: 0 | D28: 0 | E28: 0 | F28: 0 | G28: 0 | H28: 0 | I28: 0 | J28: 0 | K28: 0 | L28: 0 | M28: 0 | N28: 0 | O28: 0 | P28: 0 | Q28: 0 | R28: 0 | S28: 0 | T28: 0 | U28: 0 | V28: 0 | W28: 0 | X28: 0 | Y28: 0 | Z28: ='Mentee Blocks'!B312 -> 8.5 | AA28: ='Mentee Blocks'!C312 -> 246.5 | AB28: 0 | AC28: =SUM(B28:AB28) -> 255
A29: Sam Glick | B29: 0 | C29: 0 | D29: 0 | E29: 0 | F29: 0 | G29: 0 | H29: 0 | I29: 0 | J29: ='Mentee Blocks'!B325 -> 81.964286 | K29: ='Mentee Blocks'!C325 -> 271.74539 | L29: ='Mentee Blocks'!D325 -> 249.79032 | M29: ='Mentee Blocks'!E325 -> 260.20968 | N29: ='Mentee Blocks'!F325 -> 249.79032 | O29: ='Mentee Blocks'!G325 -> 260.20968 | P29: ='Mentee Blocks'!H325 -> 181.93548 | Q29: ='Mentee Blocks'!I325 -> 154.55484 | ... S29: ='Mentee Blocks'!K325 -> 133.35484 | T29: 0 | U29: 0 | V29: 0 | W29: 0 | X29: 0 | Y29: 0 | Z29: 0 | AA29: 0 | AB29: 0 | AC29: =SUM(B29:AB29) -> 2007
A30: Stephen Zimmerman | B30: 0 | C30: ='Mentee Blocks'!B338 -> 222.09677 | D30: ='Mentee Blocks'!C338 -> 148.06452 | E30: ='Mentee Blocks'!D338 -> 250.33871 | F30: ='Mentee Blocks'!E338 -> 251.43548 | G30: ='Mentee Blocks'!F338 -> 148.06452 | H30: 0 | I30: 0 | J30: 0 | K30: 0 | L30: 0 | M30: 0 | N30: 0 | O30: 0 | P30: 0 | Q30: 0 | R30: 0 | S30: 0 | T30: 0 | U30: 0 | V30: 0 | W30: 0 | X30: 0 | Y30: 0 | Z30: 0 | AA30: 0 | AB30: 0 | AC30: =SUM(B30:AB30) -> 1020
A31: Wynn Miller | B31: 0 | C31: 0 | D31: 0 | E31: 0 | F31: 0 | G31: 0 | H31: 0 | I31: 0 | J31: 0 | K31: 0 | L31: 0 | M31: 0 | N31: 0 | O31: 0 | P31: ='Mentee Blocks'!B351 -> 139.83871 | Q31: ='Mentee Blocks'!C351 -> 302.16129 | R31: ='Mentee Blocks'!D351 -> 257.19355 | S31: ='Mentee Blocks'!E351 -> 252.80645 | T31: ='Mentee Blocks'!F351 -> 119.29032 | U31: ='Mentee Blocks'!G351 -> 159 | V31: ='Mentee Blocks'!H351 -> 147.45968 | W31: ='Mentee Blocks'!I351 -> 170.54032 | ... Y31: ='Mentee Blocks'!K351 -> 111.3 | Z31: 0 | AA31: 0 | AB31: 0 | AC31: =SUM(B31:AB31) -> 1815
A32: TOTAL | B32: =SUM(B5:B31) -> 70.833333 | C32: =SUM(C5:C31) -> 363.76344 | D32: =SUM(D5:D31) -> 403.06452 | E32: =SUM(E5:E31) -> 556.33871 | F32: =SUM(F5:F31) -> 504.79032 | G32: =SUM(G5:G31) -> 396.20968 | H32: =SUM(H5:H31) -> 212.5 | I32: =SUM(I5:I31) -> 230.32258 | ... AC32: =SUM(AC5:AC31) -> 36692.5

Sheet June Reconciliation
A1: June 2026 — manual calculation vs the dashboard paystub
A2: Manual figures link live to the Monthly Roll-up. Dashboard figures are typed from payoutbuildharryshenk20260620260725.csv.
A4: Bridge — what explains the gap
A5: Step | B5: Amount | C5: Why
A6: Manual method as built (this workbook) | B6: =SUM(B14:B30) -> 2983.5935
A7: Step 1 — proration on a fixed 30-day month instead of real days | B7: 51.906452 | C7: The dashboard divides by 30 always; your formula divides by 31 in May.
A8: Step 2 — David Weaver's two May invoices grouped into one calendar month | B8: 144.5 | C8: Chained columns send the 17 May remainder into the 21 May column; the dashboard sends both into June.
A9: Step 3 — Josh Lehman's duplicate 4x line counted as revenue | B9: 93.5 | C9: You chose to treat it as a billing correction; the dashboard pays on it.
A10: Equals — dashboard paystub, June 2026 (Effective payout) | B10: =B6+B7+B8+B9 -> 3273.5 | C10: =B10-C31 -> 0 | D10: <- bridge minus the paystub total below; must be zero
A12: Line by line
A13: Mentee | B13: Manual (this workbook) | C13: Dashboard — Effective | D13: Variance vs Effective | E13: Dashboard — Engine (pre-review) | F13: Variance vs Engine | G13: What differs
A14: David Weaver | B14: ='Monthly Roll-up'!Z13 -> 249.24194 | C14: 399.5 | D14: =B14-C14 -> -150.25806 | E14: 399.5 | F14: =B14-E14 -> -150.25806 | G14: Two May invoices (4108 on the 17th, 4113 on the 21st). Your two-column layout keeps the 17 May remainder inside May; the dashboard rolls both May invoices into June. Plus 31-vs-30 days.
A15: Josh Lehman | B15: ='Monthly Roll-up'!Z21 -> 260.48387 | C15: 357 | D15: =B15-C15 -> -96.516129 | E15: 307.5 | F15: =B15-E15 -> -47.016129 | G15: Invoice 4109 carries two $425 4x lines. You treat the second as a correction (toggle OFF on Adjustments); the dashboard pays on both. Plus 31-vs-30 days.
A16: Kendrick Sensenig | B16: ='Monthly Roll-up'!Z22 -> 259.93548 | C16: 263.5 | D16: =B16-C16 -> -3.5645161 | E16: 245.3 | F16: =B16-E16 -> 14.635484 | G16: Proration denominator only: your formula divides the May invoice by 31 real days, the dashboard divides by a fixed 30.
A17: Brett Wengerd | B17: ='Monthly Roll-up'!Z9 -> 249.79032 | C17: 255 | D17: =B17-C17 -> -5.2096774 | E17: 255 | F17: =B17-E17 -> -5.2096774 | G17: Proration denominator only: your formula divides the May invoice by 31 real days, the dashboard divides by a fixed 30.
A18: Brandon Burkholder | B18: ='Monthly Roll-up'!Z7 -> 249.79032 | C18: 255 | D18: =B18-C18 -> -5.2096774 | E18: 255 | F18: =B18-E18 -> -5.2096774 | G18: Proration denominator only: your formula divides the May invoice by 31 real days, the dashboard divides by a fixed 30.
A19: Ike Hursh | B19: ='Monthly Roll-up'!Z16 -> 251.16129 | C19: 255 | D19: =B19-C19 -> -3.8387097 | E19: 255 | F19: =B19-E19 -> -3.8387097 | G19: Proration denominator only: your formula divides the May invoice by 31 real days, the dashboard divides by a fixed 30.
A20: Cade Byers | B20: ='Monthly Roll-up'!Z10 -> 251.43548 | C20: 255 | D20: =B20-C20 -> -3.5645161 | E20: 255 | F20: =B20-E20 -> -3.5645161 | G20: Proration denominator only: your formula divides the May invoice by 31 real days, the dashboard divides by a fixed 30.
A21: Myles Miller | B21: ='Monthly Roll-up'!Z26 -> 253.62903 | C21: 255 | D21: =B21-C21 -> -1.3709677 | E21: 255 | F21: =B21-E21 -> -1.3709677 | G21: Proration denominator only: your formula divides the May invoice by 31 real days, the dashboard divides by a fixed 30.
A22: John Troyer | B22: ='Monthly Roll-up'!Z19 -> 222.09677 | C22: 229.5 | D22: =B22-C22 -> -7.4032258 | E22: 229.5 | F22: =B22-E22 -> -7.4032258 | G22: Proration denominator only: your formula divides the May invoice by 31 real days, the dashboard divides by a fixed 30.
A23: Luke Smucker | B23: ='Monthly Roll-up'!Z25 -> 153.53226 | C23: 156 | D23: =B23-C23 -> -2.4677419 | E23: 108 | F23: =B23-E23 -> 45.532258 | G23: Proration denominator only: your formula divides the May invoice by 31 real days, the dashboard divides by a fixed 30.
A24: Alex Reiff | B24: ='Monthly Roll-up'!Z5 -> 113.50645 | C24: 115.7 | D24: =B24-C24 -> -2.1935484 | E24: 115.7 | F24: =B24-E24 -> -2.1935484 | G24: Proration denominator only: your formula divides the May invoice by 31 real days, the dashboard divides by a fixed 30.
A25: Gordon Boone | B25: ='Monthly Roll-up'!Z14 -> 110.5 | C25: 110.5 | D25: =B25-C25 -> 0 | E25: 110.5 | F25: =B25-E25 -> 0 | G25: Matches — first mentoring invoice is 17 June, and June has 30 days so both methods agree.
A26: Lavon Stoltzfus | B26: ='Monthly Roll-up'!Z24 -> 97.451613 | C26: 100.7 | D26: =B26-C26 -> -3.2483871 | E26: 100.7 | F26: =B26-E26 -> -3.2483871 | G26: Proration denominator only: your formula divides the May invoice by 31 real days, the dashboard divides by a fixed 30.
A27: Nelson Miller | B27: ='Monthly Roll-up'!Z27 -> 100.7 | C27: 100.7 | D27: =B27-C27 -> 0 | E27: 5.7 | F27: =B27-E27 -> 95 | G27: Matches — 11 June invoice, no May mentoring invoice to roll forward, 30-day month.
A28: Joel Mast | B28: ='Monthly Roll-up'!Z18 -> 85.16129 | C28: 88 | D28: =B28-C28 -> -2.8387097 | E28: 88 | F28: =B28-E28 -> -2.8387097 | G28: Proration denominator only: your formula divides the May invoice by 31 real days, the dashboard divides by a fixed 30.
A29: Daryl Bowman | B29: ='Monthly Roll-up'!Z12 -> 66.677419 | C29: 68.9 | D29: =B29-C29 -> -2.2225806 | E29: 27.3 | F29: =B29-E29 -> 39.377419 | G29: Proration denominator only: your formula divides the May invoice by 31 real days, the dashboard divides by a fixed 30.
A30: Russ Zehr | B30: ='Monthly Roll-up'!Z28 -> 8.5 | C30: 8.5 | D30: =B30-C30 -> 0 | E30: 5 | F30: =B30-E30 -> 3.5 | G30: Matches — 29 June invoice, no May mentoring invoice, 30-day month.
A31: TOTAL | B31: =SUM(B14:B30) -> 2983.5935 | C31: =SUM(C14:C30) -> 3273.5 | D31: =SUM(D14:D30) -> -289.90645 | E31: =SUM(E14:E30) -> 3017.7 | F31: =SUM(F14:F30) -> -34.106452
A33: Engine vs Effective: the dashboard's raw engine number is what it computes from the net invoice (credits applied). A reviewer removed six credit lines, which is the $255.80 difference. This workbook defaults to the same position — tier price, credits OFF.
A34: Amber fill in the Engine column = a line the reviewer overrode.

Sheet Roster
A1: Roster — Notion (source of truth) vs CoachAccountable
A2: The Notion Mentees Database is authoritative for who mentors whom. This tab shows where CoachAccountable disagrees.
A4: Notion mentee | B4: Notion status | C4: Notion mentor | D4: CA client ID | E4: CA name | F4: CA owner coach | G4: CA tier | H4: Mentoring months in data | I4: In June 2026 payout? | J4: Flag
A5: Alex Reiff | B5: 2x Mentoring | C5: Harry Shenk | D5: 277779 | E5: Alex Reiff | F5: Harry Shenk | G5: 2x | H5: 7 | I5: yes
A6: Allen Miller | B6: Done (Quit OR No Mentoring) | C6: Harry Shenk | D6: 233476 | E6: Allen Miller | F6: Harry Shenk | G6: 4x | H6: 6 | I6: no
A7: Anthony Blades | B7: 4x Mentoring | C7: Harry Shenk | D7: 302455 | E7: Anthony Blades | F7: Harry Shenk | G7: 4x | H7: 0 | I7: no
A8: Brandon Burkholder | B8: 4x Mentoring | C8: Harry Shenk | D8: 268818 | E8: Brandon Burkholder | F8: Harry Shenk | G8: 4x | H8: 7 | I8: yes
A9: Brennan Petersheim | B9: 4x Mentoring | C9: Harry Shenk | D9: 294186 | E9: Brennan Petersheim | F9: Harry Shenk | G9: 4x | H9: 1 | I9: no
A10: Brett Wengerd | B10: Done (Quit OR No Mentoring) | C10: Harry Shenk | D10: 270161 | E10: Brett Wengerd | F10: Harry Shenk | G10: 4x | H10: 10 | I10: yes
A11: Cade Byers | B11: 4x Mentoring | C11: Harry Shenk | D11: 289853 | E11: Cade Byers | F11: Harry Shenk | G11: 4x | H11: 3 | I11: yes
A12: Darin Riehl | B12: Done (Graduated) | C12: Harry Shenk | D12: 273442 | E12: Darin Riehl | F12: Harry Shenk | G12: 2x | H12: 4 | I12: no
A13: Daryl Bowman | B13: Done (Graduated) | C13: Harry Shenk | D13: 273424 | E13: Daryl Bowman | F13: Harry Shenk | G13: 2x | H13: 8 | I13: yes
A14: David Weaver | B14: 4x Mentoring | C14: Harry Shenk | D14: 282788 | E14: David Weaver | F14: Harry Shenk | G14: 4x | H14: 4 | I14: yes
A15: Everett Miller | B15: Waiting List (JYF) | C15: Harry Shenk | D15: 278176 | E15: Everett Miller | F15: Harry Shenk | G15: jumpstart | H15: 0 | I15: no
A16: Gordon Boone | B16: 4x Mentoring | C16: Harry Shenk | D16: 293922 | E16: Gordon Boone | F16: Harry Shenk | G16: 4x | H16: 2 | I16: yes
... A30: Philip Miller | B30: Waiting List (JYF) | C30: Harry Shenk | D30: 301584 | E30: Philip Miller | F30: Harry Shenk | G30: jumpstart | H30: 0 | I30: no
A31: Ralph Swartzentruber | B31: Waiting List (JYF) | C31: Harry Shenk | D31: 296245 | E31: Ralph Swartzentruber | F31: Harry Shenk | G31: jumpstart | H31: 0 | I31: no | J31: dashboard has a stored Notion coach conflict (it holds 'Phil Herschberger')
A32: Russ Zehr | B32: 4x Mentoring | C32: Harry Shenk | D32: 113068 | E32: Russ Zehr | F32: Harry Shenk | G32: 4x | H32: 1 | I32: yes
A33: Sam Glick | B33: Done (Graduated) | C33: Harry Shenk | D33: 250881 | E33: Samuel Glick | F33: Harry Shenk | G33: 2x | H33: 9 | I33: no
A34: Stephen Zimmerman | B34: Done (Quit OR No Mentoring) | C34: Harry Shenk | D34: 230660 | E34: Stephen Zimmerman | F34: Harry Shenk | G34: 4x | H34: 4 | I34: no
A35: Travis Bontrager | B35: Waiting List (JYF) | C35: Harry Shenk | D35: 296368 | E35: Travis Bontrager | F35: Harry Shenk | G35: jumpstart | H35: 0 | I35: no
A36: Wynn Miller | B36: Done (Graduated) | C36: Harry Shenk | D36: 262680 | E36: Wynn Miller | F36: Harry Shenk | G36: 2x | H36: 9 | I36: no
A39: Assigned to Harry in CoachAccountable but NOT in the Notion export
A40: CA name | B40: CA client ID | C40: CA tier | D40: CA status | E40: Notion mentor | F40: Notion status | G40: June 2026 impact
A41: Bryce Wenger | B41: 301320 | C41: 4x | D41: active | E41: ~None Assigned | F41: Waiting List (JYF) | G41: none — his 24 June invoice is JYF only. But his 23 July invoice is a $425 4x line, so he WILL matter for the July payout. Decide who owns him before then.
A42: William Beachy | B42: 252530 | C42: 2x | D42: inactive | E42: (blank) | F42: Done (Quit OR No Mentoring) | G42: none — no 2026 invoices at all.

Sheet Invoice Source Data
A1: Invoice source data — every mentoring invoice behind this workbook
A2: From the hjgrawdata 2026-07-25 export, table ca_invoices. 'Lines excluded' shows what was on the invoice but is not mentor pay.
A4: Mentee | B4: Client ID | C4: Invoice # | D4: Invoice date | E4: Mentoring line item | F4: Tier | G4: Tier price | H4: Invoice total billed | I4: Collected | J4: Lines excluded from pay | K4: Adjustment lines (see Adjustments tab)
A5: Alex Reiff | B5: 277779 | C5: 3803 | D5: 45999 | E5: MN Subscription | (4x Month) Zoom Meetings (Harry Shenk) | F5: 4x | G5: 425 | H5: 425 | I5: 425 | J5: — | K5: —
A6: Alex Reiff | B6: 277779 | C6: 3857 | D6: 46030 | E6: MN Subscription | (4x Month) Zoom Meetings (Harry Shenk) | F6: 4x | G6: 425 | H6: 425 | I6: 425 | J6: — | K6: —
A7: Alex Reiff | B7: 277779 | C7: 3910 | D7: 46061 | E7: MN Subscription | (4x Month) Zoom Meetings (Harry Shenk) | F7: 4x | G7: 425 | H7: 425 | I7: 425 | J7: — | K7: —
A8: Alex Reiff | B8: 277779 | C8: 3958 | D8: 46089 | E8: MN Subscription | (4x Month) Zoom Meetings (Harry Shenk) | F8: 4x | G8: 425 | H8: 425 | I8: 425 | J8: — | K8: —
A9: Alex Reiff | B9: 277779 | C9: 4015 | D9: 46120 | E9: MN Subscription | (4x Month) Zoom Meetings (Harry Shenk) | F9: 4x | G9: 425 | H9: 425 | I9: 425 | J9: — | K9: —
A10: Alex Reiff | B10: 277779 | C10: 4071 | D10: 46150 | E10: MN Subscription | (4x Month) Zoom Meetings (Harry Shenk) | F10: 4x | G10: 425 | H10: 425 | I10: 425 | J10: — | K10: —
A11: Alex Reiff | B11: 277779 | C11: 4170 | D11: 46194 | E11: MN Subscription | (2x Month) Zoom Meetings (Harry Shenk) | F11: 2x | G11: 265 | H11: 265 | I11: 265 | J11: — | K11: —
A12: Allen Miller | B12: 233476 | C12: 3065 | D12: 45463 | E12: JumpStart Your Freedom & One-on-One Mentoring | F12: 4x | G12: 425 | H12: 460 | I12: 460 | J12: One-Time Setup Fee ($35.00) | K12: —
A13: Allen Miller | B13: 233476 | C13: 3117 | D13: 45504 | E13: JumpStart Your Freedom & One-on-One Mentoring | F13: 4x | G13: 425 | H13: 425 | I13: 425 | J13: — | K13: —
A14: Allen Miller | B14: 233476 | C14: 3164 | D14: 45536 | E14: JumpStart Your Freedom & One-on-One Mentoring | F14: 4x | G14: 425 | H14: 425 | I14: 425 | J14: — | K14: —
A15: Allen Miller | B15: 233476 | C15: 3198 | D15: 45559 | E15: JumpStart Your Freedom & One-on-One Mentoring | F15: 4x | G15: 425 | H15: 425 | I15: 425 | J15: — | K15: —
A16: Allen Miller | B16: 233476 | C16: 3239 | D16: 45590 | E16: JumpStart Your Freedom & One-on-One Mentoring | F16: 4x | G16: 425 | H16: 425 | I16: 425 | J16: — | K16: —
... A158: Wynn Miller | B158: 262680 | C158: 4044 | D158: 46133 | E158: MN Subscription | (2x Month) Zoom Meetings (Harry Shenk) | F158: 2x | G158: 265 | H158: 265 | I158: 265 | J158: — | K158: —
A160: Pink fill in Collected = billed but not fully paid. Mentor pay is calculated on BILLED revenue, matching both your sample sheet and the dashboard.
